Warning message
An exception occurred
Traceback (most recent call last):
  File "/home/calelin/dev/direct_web_spider/tests/test_logger.py", line 108, in test_logger_exception_handling
    raise ValueError("Test exception")
ValueError: Test exception
Warning message
An exception occurred
Traceback (most recent call last):
  File "/home/calelin/dev/direct_web_spider/tests/test_logger.py", line 108, in test_logger_exception_handling
    raise ValueError("Test exception")
ValueError: Test exception
Warning message
An exception occurred
Traceback (most recent call last):
  File "/home/calelin/dev/direct_web_spider/tests/test_logger.py", line 108, in test_logger_exception_handling
    raise ValueError("Test exception")
ValueError: Test exception
Warning message
An exception occurred
Traceback (most recent call last):
  File "/home/calelin/dev/direct_web_spider/tests/test_logger.py", line 108, in test_logger_exception_handling
    raise ValueError("Test exception")
ValueError: Test exception
Warning message
An exception occurred
Traceback (most recent call last):
  File "/home/calelin/dev/direct_web_spider/tests/test_logger.py", line 108, in test_logger_exception_handling
    raise ValueError("Test exception")
ValueError: Test exception
Warning message
An exception occurred
Traceback (most recent call last):
  File "/home/calelin/dev/direct_web_spider/tests/test_logger.py", line 108, in test_logger_exception_handling
    raise ValueError("Test exception")
ValueError: Test exception
Warning message
An exception occurred
Traceback (most recent call last):
  File "/home/calelin/dev/direct_web_spider/tests/test_logger.py", line 108, in test_logger_exception_handling
    raise ValueError("Test exception")
ValueError: Test exception
Warning message
An exception occurred
Traceback (most recent call last):
  File "/home/calelin/dev/direct_web_spider/tests/test_logger.py", line 108, in test_logger_exception_handling
    raise ValueError("Test exception")
ValueError: Test exception
Warning message
An exception occurred
Traceback (most recent call last):
  File "/home/calelin/dev/direct_web_spider/tests/test_logger.py", line 108, in test_logger_exception_handling
    raise ValueError("Test exception")
ValueError: Test exception
Warning message
An exception occurred
Traceback (most recent call last):
  File "/home/calelin/dev/direct_web_spider/tests/test_logger.py", line 108, in test_logger_exception_handling
    raise ValueError("Test exception")
ValueError: Test exception
Warning message
An exception occurred
Traceback (most recent call last):
  File "/home/calelin/dev/direct_web_spider/tests/test_logger.py", line 108, in test_logger_exception_handling
    raise ValueError("Test exception")
ValueError: Test exception
Warning message
An exception occurred
Traceback (most recent call last):
  File "/home/calelin/dev/direct_web_spider/tests/test_logger.py", line 108, in test_logger_exception_handling
    raise ValueError("Test exception")
ValueError: Test exception
Warning message
An exception occurred
Traceback (most recent call last):
  File "/home/calelin/dev/direct_web_spider/tests/test_logger.py", line 108, in test_logger_exception_handling
    raise ValueError("Test exception")
ValueError: Test exception
Warning message
An exception occurred
Traceback (most recent call last):
  File "/home/calelin/dev/direct_web_spider/tests/test_logger.py", line 108, in test_logger_exception_handling
    raise ValueError("Test exception")
ValueError: Test exception
Warning message
An exception occurred
Traceback (most recent call last):
  File "/home/calelin/dev/direct_web_spider/tests/test_logger.py", line 108, in test_logger_exception_handling
    raise ValueError("Test exception")
ValueError: Test exception
Warning message
An exception occurred
Traceback (most recent call last):
  File "/home/calelin/dev/direct_web_spider/tests/test_logger.py", line 108, in test_logger_exception_handling
    raise ValueError("Test exception")
ValueError: Test exception
Warning message
An exception occurred
Traceback (most recent call last):
  File "/home/calelin/dev/direct_web_spider/tests/test_logger.py", line 108, in test_logger_exception_handling
    raise ValueError("Test exception")
ValueError: Test exception
Warning message
An exception occurred
Traceback (most recent call last):
  File "/home/calelin/dev/direct_web_spider/tests/test_logger.py", line 108, in test_logger_exception_handling
    raise ValueError("Test exception")
ValueError: Test exception
Warning message
An exception occurred
Traceback (most recent call last):
  File "/home/calelin/dev/direct_web_spider/tests/test_logger.py", line 108, in test_logger_exception_handling
    raise ValueError("Test exception")
ValueError: Test exception
Warning message
An exception occurred
Traceback (most recent call last):
  File "/home/calelin/dev/direct_web_spider/tests/test_logger.py", line 108, in test_logger_exception_handling
    raise ValueError("Test exception")
ValueError: Test exception
Warning message
An exception occurred
Traceback (most recent call last):
  File "/home/calelin/dev/direct_web_spider/tests/test_logger.py", line 108, in test_logger_exception_handling
    raise ValueError("Test exception")
ValueError: Test exception
Warning message
An exception occurred
Traceback (most recent call last):
  File "/home/calelin/dev/direct_web_spider/tests/test_logger.py", line 108, in test_logger_exception_handling
    raise ValueError("Test exception")
ValueError: Test exception
Warning message
An exception occurred
Traceback (most recent call last):
  File "/home/calelin/dev/direct_web_spider/tests/test_logger.py", line 108, in test_logger_exception_handling
    raise ValueError("Test exception")
ValueError: Test exception
Warning message
An exception occurred
Traceback (most recent call last):
  File "/home/calelin/dev/direct_web_spider/tests/test_logger.py", line 108, in test_logger_exception_handling
    raise ValueError("Test exception")
ValueError: Test exception
Warning message
An exception occurred
Traceback (most recent call last):
  File "/home/calelin/dev/direct_web_spider/tests/test_logger.py", line 108, in test_logger_exception_handling
    raise ValueError("Test exception")
ValueError: Test exception
Warning message
An exception occurred
Traceback (most recent call last):
  File "/home/calelin/dev/direct_web_spider/tests/test_logger.py", line 108, in test_logger_exception_handling
    raise ValueError("Test exception")
ValueError: Test exception
Warning message
An exception occurred
Traceback (most recent call last):
  File "/home/calelin/dev/direct_web_spider/tests/test_logger.py", line 108, in test_logger_exception_handling
    raise ValueError("Test exception")
ValueError: Test exception
Warning message
An exception occurred
Traceback (most recent call last):
  File "/home/calelin/dev/direct_web_spider/tests/test_logger.py", line 108, in test_logger_exception_handling
    raise ValueError("Test exception")
ValueError: Test exception
Warning message
An exception occurred
Traceback (most recent call last):
  File "/home/calelin/dev/direct_web_spider/tests/test_logger.py", line 108, in test_logger_exception_handling
    raise ValueError("Test exception")
ValueError: Test exception
Warning message
An exception occurred
Traceback (most recent call last):
  File "/home/calelin/dev/direct_web_spider/tests/test_logger.py", line 108, in test_logger_exception_handling
    raise ValueError("Test exception")
ValueError: Test exception
Warning message
An exception occurred
Traceback (most recent call last):
  File "/home/calelin/dev/direct_web_spider/tests/test_logger.py", line 108, in test_logger_exception_handling
    raise ValueError("Test exception")
ValueError: Test exception
Warning message
An exception occurred
Traceback (most recent call last):
  File "/home/calelin/dev/direct_web_spider/tests/test_logger.py", line 108, in test_logger_exception_handling
    raise ValueError("Test exception")
ValueError: Test exception
Warning message
An exception occurred
Traceback (most recent call last):
  File "/home/calelin/dev/direct_web_spider/tests/test_logger.py", line 108, in test_logger_exception_handling
    raise ValueError("Test exception")
ValueError: Test exception
Warning message
An exception occurred
Traceback (most recent call last):
  File "/home/calelin/dev/direct_web_spider/tests/test_logger.py", line 108, in test_logger_exception_handling
    raise ValueError("Test exception")
ValueError: Test exception
Warning message
An exception occurred
Traceback (most recent call last):
  File "/home/calelin/dev/direct_web_spider/tests/test_logger.py", line 108, in test_logger_exception_handling
    raise ValueError("Test exception")
ValueError: Test exception
Warning message
An exception occurred
Traceback (most recent call last):
  File "/home/calelin/dev/direct_web_spider/tests/test_logger.py", line 108, in test_logger_exception_handling
    raise ValueError("Test exception")
ValueError: Test exception
Warning message
An exception occurred
Traceback (most recent call last):
  File "/home/calelin/dev/direct_web_spider/tests/test_logger.py", line 108, in test_logger_exception_handling
    raise ValueError("Test exception")
ValueError: Test exception
Warning message
An exception occurred
Traceback (most recent call last):
  File "/home/calelin/dev/direct_web_spider/tests/test_logger.py", line 108, in test_logger_exception_handling
    raise ValueError("Test exception")
ValueError: Test exception
Warning message
An exception occurred
Traceback (most recent call last):
  File "/home/calelin/dev/direct_web_spider/tests/test_logger.py", line 108, in test_logger_exception_handling
    raise ValueError("Test exception")
ValueError: Test exception
Warning message
An exception occurred
Traceback (most recent call last):
  File "/home/calelin/dev/direct_web_spider/tests/test_logger.py", line 108, in test_logger_exception_handling
    raise ValueError("Test exception")
ValueError: Test exception
Warning message
An exception occurred
Traceback (most recent call last):
  File "/home/calelin/dev/direct_web_spider/tests/test_logger.py", line 108, in test_logger_exception_handling
    raise ValueError("Test exception")
ValueError: Test exception
Warning message
An exception occurred
Traceback (most recent call last):
  File "/home/calelin/dev/direct_web_spider/tests/test_logger.py", line 108, in test_logger_exception_handling
    raise ValueError("Test exception")
ValueError: Test exception
Warning message
An exception occurred
Traceback (most recent call last):
  File "/home/calelin/dev/direct_web_spider/tests/test_logger.py", line 108, in test_logger_exception_handling
    raise ValueError("Test exception")
ValueError: Test exception
Warning message
An exception occurred
Traceback (most recent call last):
  File "/home/calelin/dev/direct_web_spider/tests/test_logger.py", line 108, in test_logger_exception_handling
    raise ValueError("Test exception")
ValueError: Test exception
Warning message
An exception occurred
Traceback (most recent call last):
  File "/home/calelin/dev/direct_web_spider/tests/test_logger.py", line 108, in test_logger_exception_handling
    raise ValueError("Test exception")
ValueError: Test exception
Warning message
An exception occurred
Traceback (most recent call last):
  File "/home/calelin/dev/direct_web_spider/tests/test_logger.py", line 108, in test_logger_exception_handling
    raise ValueError("Test exception")
ValueError: Test exception
Warning message
An exception occurred
Traceback (most recent call last):
  File "/home/calelin/dev/direct_web_spider/tests/test_logger.py", line 108, in test_logger_exception_handling
    raise ValueError("Test exception")
ValueError: Test exception
Warning message
An exception occurred
Traceback (most recent call last):
  File "/home/calelin/dev/direct_web_spider/tests/test_logger.py", line 108, in test_logger_exception_handling
    raise ValueError("Test exception")
ValueError: Test exception
Warning message
An exception occurred
Traceback (most recent call last):
  File "/home/calelin/dev/direct_web_spider/tests/test_logger.py", line 108, in test_logger_exception_handling
    raise ValueError("Test exception")
ValueError: Test exception
Warning message
An exception occurred
Traceback (most recent call last):
  File "/home/calelin/dev/direct_web_spider/tests/test_logger.py", line 108, in test_logger_exception_handling
    raise ValueError("Test exception")
ValueError: Test exception
Warning message
An exception occurred
Traceback (most recent call last):
  File "/home/calelin/dev/direct_web_spider/tests/test_logger.py", line 108, in test_logger_exception_handling
    raise ValueError("Test exception")
ValueError: Test exception
Warning message
An exception occurred
Traceback (most recent call last):
  File "/home/calelin/dev/direct_web_spider/tests/test_logger.py", line 108, in test_logger_exception_handling
    raise ValueError("Test exception")
ValueError: Test exception
Warning message
An exception occurred
Traceback (most recent call last):
  File "/home/calelin/dev/direct_web_spider/tests/test_logger.py", line 108, in test_logger_exception_handling
    raise ValueError("Test exception")
ValueError: Test exception
Warning message
An exception occurred
Traceback (most recent call last):
  File "/home/calelin/dev/direct_web_spider/tests/test_logger.py", line 108, in test_logger_exception_handling
    raise ValueError("Test exception")
ValueError: Test exception
Warning message
An exception occurred
Traceback (most recent call last):
  File "/home/calelin/dev/direct_web_spider/tests/test_logger.py", line 108, in test_logger_exception_handling
    raise ValueError("Test exception")
ValueError: Test exception
Warning message
An exception occurred
Traceback (most recent call last):
  File "/home/calelin/dev/direct_web_spider/tests/test_logger.py", line 108, in test_logger_exception_handling
    raise ValueError("Test exception")
ValueError: Test exception
Warning message
An exception occurred
Traceback (most recent call last):
  File "/home/calelin/dev/direct_web_spider/tests/test_logger.py", line 108, in test_logger_exception_handling
    raise ValueError("Test exception")
ValueError: Test exception
Warning message
An exception occurred
Traceback (most recent call last):
  File "/home/calelin/dev/direct_web_spider/tests/test_logger.py", line 108, in test_logger_exception_handling
    raise ValueError("Test exception")
ValueError: Test exception
Warning message
An exception occurred
Traceback (most recent call last):
  File "/home/calelin/dev/direct_web_spider/tests/test_logger.py", line 108, in test_logger_exception_handling
    raise ValueError("Test exception")
ValueError: Test exception
Warning message
An exception occurred
Traceback (most recent call last):
  File "/home/calelin/dev/direct_web_spider/tests/test_logger.py", line 108, in test_logger_exception_handling
    raise ValueError("Test exception")
ValueError: Test exception
Warning message
An exception occurred
Traceback (most recent call last):
  File "/home/calelin/dev/direct_web_spider/tests/test_logger.py", line 108, in test_logger_exception_handling
    raise ValueError("Test exception")
ValueError: Test exception
Warning message
An exception occurred
Traceback (most recent call last):
  File "/home/calelin/dev/direct_web_spider/tests/test_logger.py", line 108, in test_logger_exception_handling
    raise ValueError("Test exception")
ValueError: Test exception
